Workbook

Sheet 总览与理性分析
A2: 苏州八地人才政策对比
A3: 依据本次上传八份Word整理 · 2026-10-10 · 姑苏区为区级计划 · 数额均不代表无条件到账
A5: 地区 | B5: 常规创业资助（万元） | C5: 创业住房参考（万元） | D5: 项目拨付信息 | E5: 主要判断
A6: 吴中（东吴） | B6: 100—300 | C6: 全类别新范围50—200；创业分档待核 | D6: 50/30/20明确 | E6: 住房与团队门槛有文内冲突
A7: 姑苏区（区级） | B7: 最高100 | C7: 最高100 | D7: 按进度分期，比例未列 | E7: 区级≠市级；2026批次待核
A8: 常熟（昆承） | B8: 未确认 | C8: 最高150 | D8: 新版本比例缺失 | E8: 常规资金缺失，待落户综合160/40
A9: 昆山 | B9: 100 / 200 / 300 / 400 | C9: 最高60 | D9: 70/30或50/50跨版待核 | E9: 最高创业400；资金条款版本需核
A10: 工业园区（金鸡湖） | B10: 100或300（非连续档） | C10: 100—150 | D10: 分期，比例未列 | E10: 常规与重大/成长分开，创新为综合补贴
A11: 高新区 | B11: 100 / 200 / 300 | C11: 最高100 | D11: 比例未核实 | E11: 300万创业档需个人实缴500万
A12: 吴江 | B12: 100 / 200 / 300 | C12: 50 / 100 / 150 | D12: 新版比例未列 | E12: 房票试行期临近届满
A13: 相城 | B13: 50 / 100 | C13: 最高100 | D13: 分年度，比例未列 | E13: 普通创业50/100；300为特别优秀上浮
A16: 如何阅读排名
A18: 说明项 | B18: 解释
A19: 排序规则 | B19: 各图按同类最高值由低到高排列，同额保持数据表顺序。最低值和最高值分列；离散档次保留原文，不能假设区间内任意金额均可获批。
A20: 范围与缺失 | B20: 最低空白是未明确，不是0。常熟常规现行金额不参加排名；姑苏区创新项目经费0来自文档明确无此项。
A21: 不能相加 | B21: 项目补助、综合扶持、个人住房、企业引才奖励、贷款及股权投资分开。不同级别或互斥住房待遇不汇总成“最高总包”。
A22: 雷达图 | B22: 四个资料较完整地区，用常规创业、企业创新、常规团队、创业住房上限，除以四地相应最高值。表示相对额度，不是获评率或综合优劣评分。
A23: 数据更新 | B23: 输入金额可编辑，金额页排序公式及关联图表随对应数字变化；贷款表排序为本次快照。若修改类别/政策性质或补入缺失地区，需同步扩展图表源范围；分析文字是本次整理结论。
A26: 理性分析与选择条件
A28: 比较维度 | B28: 根据附件可得的判断 | C28: 使用建议
A29: 普通创业经费 | B29: 常规上限：相城与姑苏区100；吴中、园区、高新区、吴江300；昆山400。常熟缺失不能视为最少。相城特别优秀300、园区重大1000等未混入常规。 | C29: 先确认申报类别和可达到的实际档次，金额上限不能替代资格判断。
A30: 实际出资约束 | B30: 八地常规创业基本个人现金门槛均为100万。高新区200/300万档另需个人实缴300/500万；园区300万档要求企业实缴300万，个人与企业口径不同。 | C30: 高额度对应更多资金或成长条件；以自有资金、技术和经营证据匹配档次。
A31: 现金流可见性 | B31: 东吴本表有现行50/30/20明确节点：100—300万创业档对应首笔50—150万。其他多数未明确比例；昆山比例需解决版本问题。 | C31: 首笔可申请与到账不同；不预先把资助总额安排成第一年可用资金。
A32: 住房支持 | B32: 同为创业个人，昆山上限60；姑苏区、高新区、相城100；园区、吴江150。吴中创业新档次待核，常熟房票150来自2025说明。 | C32: 先核房屋地点、购房款比例、产权、期限及租购互抵；房票与现金补贴使用方式不同。
A33: 创新及团队 | B33: 企业创新上限昆山200、吴江150、吴中/高新区/相城100；姑苏区无项目经费。园区50—100为综合补贴。团队600/800/1000各有不同人数投入条件。 | C33: 创新人才比较时同时看聘用年薪和连续服务；团队先核门槛，不与个人资助混排。
A34: 产业和配套 | B34: 园区强调信息技术、装备及生物医药等；高新区有光子方向；昆山人工智能/集成电路；其他区亦有各自产业范围。贷款与股权支持均有审核及交易条件。 | C34: 通过属地核实产业链、场地和客户资源；不将贷款额度当作无偿收益。
A35: 历史数量能说明什么 | B35: 目前各地年份、批次、拟/正式及计量单位不一致；多数缺申报分母。东吴47/77和梅李1/6仅是局部文档口径。 | C35: 不据这些数字评出“最容易申报地区”，也不以人次累计或年度目标替代实绩。
A36: 当前需要补齐 | B36: 优先解决常熟新细则完整资金条款、吴中住房与团队冲突、昆山新版拨付依据、吴江房票续期、姑苏2026批次等。 | C36: 确认书面口径后再签约、购房或确定资金预算。
A40: 文内冲突及缺口登记
A42: 事项 | B42: 发现的问题 | C42: 本表处理 | D42: 待补材料 | E42: 定位
A43: 吴中住房 | B43: 总览团队150—250与后文2026新细则50—200冲突 | C43: 采用后文新范围作全类别参考；创业分档不用于同口径住房排名 | D43: 2026年度申领通知及新细则分档表 | E43: 东吴 B32、B51—56
A44: 吴中团队投入 | B44: 总览3年≥3000万；流程总≥1亿且已≥3000万 | C44: 金额资助可列；投入门槛不参与跨地排名 | D44: 当批团队通知和实施细则 | E44: 东吴 B28、B80
A45: 昆山拨付版本 | B45: 自称2026规则，但引用包含2024/2021资金文件 | C45: 保留70/30与50/50为待核，不纳入确定首拨测算 | D45: 昆委人才办〔2026〕3号原件资金条款 | E45: 昆山 B42、B60—61、B154—162
A46: 昆山未落户期限 | B46: 同段写一年内落户，又写资格有效期2年 | C46: 分别保留，不选任意一个当作唯一期限 | D46: 2026未落户专项通知 | E46: 昆山 B38、B131
A47: 常熟新旧政策 | B47: 2025细则资金全文未取得；旧160—600等易混入 | C47: 现行常规金额缺失；仅列待落户160/40综合扶持 | D47: 2025细则与2026合同 | E47: 常熟 B24—40
A48: 姑苏统计 | B48: 12+10+20标成四个批次，且称可比较未知全年 | C48: 更正为三个已知批次；保留拟认定，不计算年增长 | D48: 缺失批次正式名单和申报分母 | E48: 姑苏 B65—67
A49: 姑苏身份 | B49: 区级姑苏与市级姑苏同名、服务卡资格描述较绝对 | C49: 仅比较区级计划；分类及服务资格另核，不自动升级 | D49: 人才分类目录及各服务受理规则 | E49: 姑苏 B16、B72—93
A50: 吴江房票效力 | B50: 2025/10/24起试行1年，临近2026届满 | C50: 保留原效期；12个月单票期限不自动延长政策 | D50: 续期文件与跨期房票办理答复 | E50: 吴江 B11、B37—42
A51: 园区创新金额 | B51: 50—100为综合补贴，非单列纯项目经费 | C51: 创新图明确性质，不与纯项目资金硬合并 | D51: 协议中补贴构成 | E51: 园区 B7、B26、B38
A52: 各地历史数量 | B52: 人数/项目、全年度/单批、拟/正式、上级/区级混合 | C52: 保留维度，不作八地立项总量或通过率总排名 | D52: 相同年份批次全量申报和正式立项名单 | E52: 见历史数据表
...

Sheet 金额排序与图表
A2: 金额区间与上限排序
A3: 从低到高 · 单位：万元 · 青色=明确最低档，蓝色=最高档；仅上限的最低留空，不按0显示。
A5: 常规创业项目资助
A6: 常熟金额未确认，未入图；相城特别优秀上浮、孵化、成长及重大类别均未计入。
A27: 地区 | B27: 明确最低档 | C27: 最高档 | D27: 档次说明 | E27: 上限升序位次 | F27: 源序号 | N27: 候选地区 | O27: 明确最低档 | P27: 最高档 | Q27: 档次说明 | R27: 排序键 | S27: 源序号
A28: =INDEX(N$28:N$34,MATCH(E28,$R$28:$R$34,0)) -> 姑苏区 | B28: =INDEX(O$28:O$34,MATCH(E28,$R$28:$R$34,0)) | C28: =INDEX(P$28:P$34,MATCH(E28,$R$28:$R$34,0)) -> 100 | D28: =INDEX(Q$28:Q$34,MATCH(E28,$R$28:$R$34,0)) -> 最高100 | E28: 1 | F28: =INDEX(S$28:S$34,MATCH(E28,$R$28:$R$34,0)) -> 2 | N28: 吴中 | O28: =IF(ISNUMBER(政策金额数据!E6),政策金额数据!E6,"") -> 100 | P28: =IF(ISNUMBER(政策金额数据!F6),政策金额数据!F6,"") -> 300 | Q28: =政策金额数据!G6 -> 100—300 | R28: =COUNTIFS($P$28:$P$34,"<"&P28)+COUNTIFS($P$28:P28,P28) -> 3 | S28: 1
A29: =INDEX(N$28:N$34,MATCH(E29,$R$28:$R$34,0)) -> 相城 | B29: =INDEX(O$28:O$34,MATCH(E29,$R$28:$R$34,0)) -> 50 | C29: =INDEX(P$28:P$34,MATCH(E29,$R$28:$R$34,0)) -> 100 | D29: =INDEX(Q$28:Q$34,MATCH(E29,$R$28:$R$34,0)) -> 50 / 100 | E29: 2 | F29: =INDEX(S$28:S$34,MATCH(E29,$R$28:$R$34,0)) -> 8 | N29: 姑苏区 | O29: =IF(ISNUMBER(政策金额数据!E7),政策金额数据!E7,"") | P29: =IF(ISNUMBER(政策金额数据!F7),政策金额数据!F7,"") -> 100 | Q29: =政策金额数据!G7 -> 最高100 | R29: =COUNTIFS($P$28:$P$34,"<"&P29)+COUNTIFS($P$28:P29,P29) -> 1 | S29: 2
A30: =INDEX(N$28:N$34,MATCH(E30,$R$28:$R$34,0)) -> 吴中 | B30: =INDEX(O$28:O$34,MATCH(E30,$R$28:$R$34,0)) -> 100 | C30: =INDEX(P$28:P$34,MATCH(E30,$R$28:$R$34,0)) -> 300 | D30: =INDEX(Q$28:Q$34,MATCH(E30,$R$28:$R$34,0)) -> 100—300 | E30: 3 | F30: =INDEX(S$28:S$34,MATCH(E30,$R$28:$R$34,0)) -> 1 | N30: 昆山 | O30: =IF(ISNUMBER(政策金额数据!E9),政策金额数据!E9,"") -> 100 | P30: =IF(ISNUMBER(政策金额数据!F9),政策金额数据!F9,"") -> 400 | Q30: =政策金额数据!G9 -> 100 / 200 / 300 / 400 | R30: =COUNTIFS($P$28:$P$34,"<"&P30)+COUNTIFS($P$28:P30,P30) -> 7 | S30: 4
A31: =INDEX(N$28:N$34,MATCH(E31,$R$28:$R$34,0)) -> 园区 | B31: =INDEX(O$28:O$34,MATCH(E31,$R$28:$R$34,0)) -> 100 | C31: =INDEX(P$28:P$34,MATCH(E31,$R$28:$R$34,0)) -> 300 | D31: =INDEX(Q$28:Q$34,MATCH(E31,$R$28:$R$34,0)) -> 100或300（非连续档） | E31: 4 | F31: =INDEX(S$28:S$34,MATCH(E31,$R$28:$R$34,0)) -> 5 | N31: 园区 | O31: =IF(ISNUMBER(政策金额数据!E10),政策金额数据!E10,"") -> 100 | P31: =IF(ISNUMBER(政策金额数据!F10),政策金额数据!F10,"") -> 300 | Q31: =政策金额数据!G10 -> 100或300（非连续档） | R31: =COUNTIFS($P$28:$P$34,"<"&P31)+COUNTIFS($P$28:P31,P31) -> 4 | S31: 5
A32: =INDEX(N$28:N$34,MATCH(E32,$R$28:$R$34,0)) -> 高新区 | B32: =INDEX(O$28:O$34,MATCH(E32,$R$28:$R$34,0)) -> 100 | C32: =INDEX(P$28:P$34,MATCH(E32,$R$28:$R$34,0)) -> 300 | D32: =INDEX(Q$28:Q$34,MATCH(E32,$R$28:$R$34,0)) -> 100 / 200 / 300 | E32: 5 | F32: =INDEX(S$28:S$34,MATCH(E32,$R$28:$R$34,0)) -> 6 | N32: 高新区 | O32: =IF(ISNUMBER(政策金额数据!E11),政策金额数据!E11,"") -> 100 | P32: =IF(ISNUMBER(政策金额数据!F11),政策金额数据!F11,"") -> 300 | Q32: =政策金额数据!G11 -> 100 / 200 / 300 | R32: =COUNTIFS($P$28:$P$34,"<"&P32)+COUNTIFS($P$28:P32,P32) -> 5 | S32: 6
A33: =INDEX(N$28:N$34,MATCH(E33,$R$28:$R$34,0)) -> 吴江 | B33: =INDEX(O$28:O$34,MATCH(E33,$R$28:$R$34,0)) -> 100 | C33: =INDEX(P$28:P$34,MATCH(E33,$R$28:$R$34,0)) -> 300 | D33: =INDEX(Q$28:Q$34,MATCH(E33,$R$28:$R$34,0)) -> 100 / 200 / 300 | E33: 6 | F33: =INDEX(S$28:S$34,MATCH(E33,$R$28:$R$34,0)) -> 7 | N33: 吴江 | O33: =IF(ISNUMBER(政策金额数据!E12),政策金额数据!E12,"") -> 100 | P33: =IF(ISNUMBER(政策金额数据!F12),政策金额数据!F12,"") -> 300 | Q33: =政策金额数据!G12 -> 100 / 200 / 300 | R33: =COUNTIFS($P$28:$P$34,"<"&P33)+COUNTIFS($P$28:P33,P33) -> 6 | S33: 7
A34: =INDEX(N$28:N$34,MATCH(E34,$R$28:$R$34,0)) -> 昆山 | B34: =INDEX(O$28:O$34,MATCH(E34,$R$28:$R$34,0)) -> 100 | C34: =INDEX(P$28:P$34,MATCH(E34,$R$28:$R$34,0)) -> 400 | D34: =INDEX(Q$28:Q$34,MATCH(E34,$R$28:$R$34,0)) -> 100 / 200 / 300 / 400 | E34: 7 | F34: =INDEX(S$28:S$34,MATCH(E34,$R$28:$R$34,0)) -> 4 | N34: 相城 | O34: =IF(ISNUMBER(政策金额数据!E13),政策金额数据!E13,"") -> 50 | P34: =IF(ISNUMBER(政策金额数据!F13),政策金额数据!F13,"") -> 100 | Q34: =政策金额数据!G13 -> 50 / 100 | R34: =COUNTIFS($P$28:$P$34,"<"&P34)+COUNTIFS($P$28:P34,P34) -> 2 | S34: 8
A40: 个人创新项目资助
A41: 常熟未确认；园区50—100为综合补贴单列于政策数据；姑苏区0表示明确无项目资助。
A62: 地区 | B62: 明确最低档 | C62: 最高档 | D62: 档次说明 | E62: 上限升序位次 | F62: 源序号 | N62: 候选地区 | O62: 明确最低档 | P62: 最高档 | Q62: 档次说明 | R62: 排序键 | S62: 源序号
A63: =INDEX(N$63:N$68,MATCH(E63,$R$63:$R$68,0)) -> 姑苏区 | B63: =INDEX(O$63:O$68,MATCH(E63,$R$63:$R$68,0)) -> 0 | C63: =INDEX(P$63:P$68,MATCH(E63,$R$63:$R$68,0)) -> 0 | D63: =INDEX(Q$63:Q$68,MATCH(E63,$R$63:$R$68,0)) -> 无项目资助 | E63: 1 | F63: =INDEX(S$63:S$68,MATCH(E63,$R$63:$R$68,0)) -> 10 | N63: 吴中 | O63: =IF(ISNUMBER(政策金额数据!E14),政策金额数据!E14,"") -> 50 | P63: =IF(ISNUMBER(政策金额数据!F14),政策金额数据!F14,"") -> 100 | Q63: =政策金额数据!G14 -> 50—100 | R63: =COUNTIFS($P$63:$P$68,"<"&P63)+COUNTIFS($P$63:P63,P63) -> 2 | S63: 9
A64: =INDEX(N$63:N$68,MATCH(E64,$R$63:$R$68,0)) -> 吴中 | B64: =INDEX(O$63:O$68,MATCH(E64,$R$63:$R$68,0)) -> 50 | C64: =INDEX(P$63:P$68,MATCH(E64,$R$63:$R$68,0)) -> 100 | D64: =INDEX(Q$63:Q$68,MATCH(E64,$R$63:$R$68,0)) -> 50—100 | E64: 2 | F64: =INDEX(S$63:S$68,MATCH(E64,$R$63:$R$68,0)) -> 9 | N64: 姑苏区 | O64: =IF(ISNUMBER(政策金额数据!E15),政策金额数据!E15,"") -> 0 | P64: =IF(ISNUMBER(政策金额数据!F15),政策金额数据!F15,"") -> 0 | Q64: =政策金额数据!G15 -> 无项目资助 | R64: =COUNTIFS($P$63:$P$68,"<"&P64)+COUNTIFS($P$63:P64,P64) -> 1 | S64: 10
A65: =INDEX(N$63:N$68,MATCH(E65,$R$63:$R$68,0)) -> 高新区 | B65: =INDEX(O$63:O$68,MATCH(E65,$R$63:$R$68,0)) -> 50 | C65: =INDEX(P$63:P$68,MATCH(E65,$R$63:$R$68,0)) -> 100 | D65: =INDEX(Q$63:Q$68,MATCH(E65,$R$63:$R$68,0)) -> 50 / 100 | E65: 3 | F65: =INDEX(S$63:S$68,MATCH(E65,$R$63:$R$68,0)) -> 14 | N65: 昆山 | O65: =IF(ISNUMBER(政策金额数据!E17),政策金额数据!E17,"") -> 100 | P65: =IF(ISNUMBER(政策金额数据!F17),政策金额数据!F17,"") -> 200 | Q65: =政策金额数据!G17 -> 100 / 200 | R65: =COUNTIFS($P$63:$P$68,"<"&P65)+COUNTIFS($P$63:P65,P65) -> 6 | S65: 12
A66: =INDEX(N$63:N$68,MATCH(E66,$R$63:$R$68,0)) -> 相城 | B66: =INDEX(O$63:O$68,MATCH(E66,$R$63:$R$68,0)) -> 50 | C66: =INDEX(P$63:P$68,MATCH(E66,$R$63:$R$68,0)) -> 100 | D66: =INDEX(Q$63:Q$68,MATCH(E66,$R$63:$R$68,0)) -> 50 / 80 / 100 | E66: 4 | F66: =INDEX(S$63:S$68,MATCH(E66,$R$63:$R$68,0)) -> 16 | N66: 高新区 | O66: =IF(ISNUMBER(政策金额数据!E19),政策金额数据!E19,"") -> 50 | P66: =IF(ISNUMBER(政策金额数据!F19),政策金额数据!F19,"") -> 100 | Q66: =政策金额数据!G19 -> 50 / 100 | R66: =COUNTIFS($P$63:$P$68,"<"&P66)+COUNTIFS($P$63:P66,P66) -> 3 | S66: 14
A67: =INDEX(N$63:N$68,MATCH(E67,$R$63:$R$68,0)) -> 吴江 | B67: =INDEX(O$63:O$68,MATCH(E67,$R$63:$R$68,0)) -> 50 | C67: =INDEX(P$63:P$68,MATCH(E67,$R$63:$R$68,0)) -> 150 | D67: =INDEX(Q$63:Q$68,MATCH(E67,$R$63:$R$68,0)) -> 50 / 100 / 150 | E67: 5 | F67: =INDEX(S$63:S$68,MATCH(E67,$R$63:$R$68,0)) -> 15 | N67: 吴江 | O67: =IF(ISNUMBER(政策金额数据!E20),政策金额数据!E20,"") -> 50 | P67: =IF(ISNUMBER(政策金额数据!F20),政策金额数据!F20,"") -> 150 | Q67: =政策金额数据!G20 -> 50 / 100 / 150 | R67: =COUNTIFS($P$63:$P$68,"<"&P67)+COUNTIFS($P$63:P67,P67) -> 5 | S67: 15
A68: =INDEX(N$63:N$68,MATCH(E68,$R$63:$R$68,0)) -> 昆山 | B68: =INDEX(O$63:O$68,MATCH(E68,$R$63:$R$68,0)) -> 100 | C68: =INDEX(P$63:P$68,MATCH(E68,$R$63:$R$68,0)) -> 200 | D68: =INDEX(Q$63:Q$68,MATCH(E68,$R$63:$R$68,0)) -> 100 / 200 | E68: 6 | F68: =INDEX(S$63:S$68,MATCH(E68,$R$63:$R$68,0)) -> 12 | N68: 相城 | O68: =IF(ISNUMBER(政策金额数据!E21),政策金额数据!E21,"") -> 50 | P68: =IF(ISNUMBER(政策金额数据!F21),政策金额数据!F21,"") -> 100 | Q68: =政策金额数据!G21 -> 50 / 80 / 100 | R68: =COUNTIFS($P$63:$P$68,"<"&P68)+COUNTIFS($P$63:P68,P68) -> 4 | S68: 16
A75: 常规团队项目资助
A76: 不同团队类型门槛见申报表；高新区顶尖1000—5000、园区重大创业300—1000另列。
A97: 地区 | B97: 明确最低档 | C97: 最高档 | D97: 档次说明 | E97: 上限升序位次 | F97: 源序号 | N97: 候选地区 | O97: 明确最低档 | P97: 最高档 | Q97: 档次说明 | R97: 排序键 | S97: 源序号
A98: =INDEX(N$98:N$102,MATCH(E98,$R$98:$R$102,0)) -> 高新区 | B98: =INDEX(O$98:O$102,MATCH(E98,$R$98:$R$102,0)) -> 400 | C98: =INDEX(P$98:P$102,MATCH(E98,$R$98:$R$102,0)) -> 600 | D98: =INDEX(Q$98:Q$102,MATCH(E98,$R$98:$R$102,0)) -> 400 / 500 / 600 | E98: 1 | F98: =INDEX(S$98:S$102,MATCH(E98,$R$98:$R$102,0)) -> 22 | N98: 吴中 | O98: =IF(ISNUMBER(政策金额数据!E22),政策金额数据!E22,"") -> 300 | P98: =IF(ISNUMBER(政策金额数据!F22),政策金额数据!F22,"") -> 1000 | Q98: =政策金额数据!G22 -> 300—1000 | R98: =COUNTIFS($P$98:$P$102,"<"&P98)+COUNTIFS($P$98:P98,P98) -> 3 | S98: 17
A99: =INDEX(N$98:N$102,MATCH(E99,$R$98:$R$102,0)) -> 相城 | B99: =INDEX(O$98:O$102,MATCH(E99,$R$98:$R$102,0)) -> 400 | C99: =INDEX(P$98:P$102,MATCH(E99,$R$98:$R$102,0)) -> 800 | D99: =INDEX(Q$98:Q$102,MATCH(E99,$R$98:$R$102,0)) -> 400 / 600 / 800 | E99: 2 | F99: =INDEX(S$98:S$102,MATCH(E99,$R$98:$R$102,0)) -> 24 | N99: 昆山 | O99: =IF(ISNUMBER(政策金额数据!E25),政策金额数据!E25,"") -> 400 | P99: =IF(ISNUMBER(政策金额数据!F25),政策金额数据!F25,"") -> 1000 | Q99: =政策金额数据!G25 -> 400 / 500 / 1000 | R99: =COUNTIFS($P$98:$P$102,"<"&P99)+COUNTIFS($P$98:P99,P99) -> 4 | S99: 20
A100: =INDEX(N$98:N$102,MATCH(E100,$R$98:$R$102,0)) -> 吴中 | B100: =INDEX(O$98:O$102,MATCH(E100,$R$98:$R$102,0)) -> 300 | C100: =INDEX(P$98:P$102,MATCH(E100,$R$98:$R$102,0)) -> 1000 | D100: =INDEX(Q$98:Q$102,MATCH(E100,$R$98:$R$102,0)) -> 300—1000 | E100: 3 | F100: =INDEX(S$98:S$102,MATCH(E100,$R$98:$R$102,0)) -> 17 | N100: 高新区 | O100: =IF(ISNUMBER(政策金额数据!E27),政策金额数据!E27,"") -> 400 | P100: =IF(ISNUMBER(政策金额数据!F27),政策金额数据!F27,"") -> 600 | Q100: =政策金额数据!G27 -> 400 / 500 / 600 | R100: =COUNTIFS($P$98:$P$102,"<"&P100)+COUNTIFS($P$98:P100,P100) -> 1 | S100: 22
A101: =INDEX(N$98:N$102,MATCH(E101,$R$98:$R$102,0)) -> 昆山 | B101: =INDEX(O$98:O$102,MATCH(E101,$R$98:$R$102,0)) -> 400 | C101: =INDEX(P$98:P$102,MATCH(E101,$R$98:$R$102,0)) -> 1000 | D101: =INDEX(Q$98:Q$102,MATCH(E101,$R$98:$R$102,0)) -> 400 / 500 / 1000 | E101: 4 | F101: =INDEX(S$98:S$102,MATCH(E101,$R$98:$R$102,0)) -> 20 | N101: 吴江 | O101: =IF(ISNUMBER(政策金额数据!E28),政策金额数据!E28,"") -> 300 | P101: =IF(ISNUMBER(政策金额数据!F28),政策金额数据!F28,"") -> 1000 | Q101: =政策金额数据!G28 -> 300 / 500 / 1000 | R101: =COUNTIFS($P$98:$P$102,"<"&P101)+COUNTIFS($P$98:P101,P101) -> 5 | S101: 23
A102: =INDEX(N$98:N$102,MATCH(E102,$R$98:$R$102,0)) -> 吴江 | B102: =INDEX(O$98:O$102,MATCH(E102,$R$98:$R$102,0)) -> 300 | C102: =INDEX(P$98:P$102,MATCH(E102,$R$98:$R$102,0)) -> 1000 | D102: =INDEX(Q$98:Q$102,MATCH(E102,$R$98:$R$102,0)) -> 300 / 500 / 1000 | E102: 5 | F102: =INDEX(S$98:S$102,MATCH(E102,$R$98:$R$102,0)) -> 23 | N102: 相城 | O102: =IF(ISNUMBER(政策金额数据!E29),政策金额数据!E29,"") -> 400 | P102: =IF(ISNUMBER(政策金额数据!F29),政策金额数据!F29,"") -> 800 | Q102: =政策金额数据!G29 -> 400 / 600 / 800 | R102: =COUNTIFS($P$98:$P$102,"<"&P102)+COUNTIFS($P$98:P102,P102) -> 2 | S102: 24
A110: 创业个人住房支持
A111: 园区/吴江有明确范围；其余只给上限。吴中新创业分档、常熟2026档次待核，未入图。
A132: 地区 | B132: 明确最低档 | C132: 最高档 | D132: 档次说明 | E132: 上限升序位次 | F132: 源序号 | N132: 候选地区 | O132: 明确最低档 | P132: 最高档 | Q132: 档次说明 | R132: 排序键 | S132: 源序号
A133: =INDEX(N$133:N$138,MATCH(E133,$R$133:$R$138,0)) -> 昆山 | B133: =INDEX(O$133:O$138,MATCH(E133,$R$133:$R$138,0)) | C133: =INDEX(P$133:P$138,MATCH(E133,$R$133:$R$138,0)) -> 60 | D133: =INDEX(Q$133:Q$138,MATCH(E133,$R$133:$R$138,0)) -> 最高60 | E133: 1 | F133: =INDEX(S$133:S$138,MATCH(E133,$R$133:$R$138,0)) -> 28 | N133: 姑苏区 | O133: =IF(ISNUMBER(政策金额数据!E31),政策金额数据!E31,"") | P133: =IF(ISNUMBER(政策金额数据!F31),政策金额数据!F31,"") -> 100 | Q133: =政策金额数据!G31 -> 最高100 | R133: =COUNTIFS($P$133:$P$138,"<"&P133)+COUNTIFS($P$133:P133,P133) -> 2 | S133: 26
A134: =INDEX(N$133:N$138,MATCH(E134,$R$133:$R$138,0)) -> 姑苏区 | B134: =INDEX(O$133:O$138,MATCH(E134,$R$133:$R$138,0)) | C134: =INDEX(P$133:P$138,MATCH(E134,$R$133:$R$138,0)) -> 100 | D134: =INDEX(Q$133:Q$138,MATCH(E134,$R$133:$R$138,0)) -> 最高100 | E134: 2 | F134: =INDEX(S$133:S$138,MATCH(E134,$R$133:$R$138,0)) -> 26 | N134: 昆山 | O134: =IF(ISNUMBER(政策金额数据!E33),政策金额数据!E33,"") | P134: =IF(ISNUMBER(政策金额数据!F33),政策金额数据!F33,"") -> 60 | Q134: =政策金额数据!G33 -> 最高60 | R134: =COUNTIFS($P$133:$P$138,"<"&P134)+COUNTIFS($P$133:P134,P134) -> 1 | S134: 28
A135: =INDEX(N$133:N$138,MATCH(E135,$R$133:$R$138,0)) -> 高新区 | B135: =INDEX(O$133:O$138,MATCH(E135,$R$133:$R$138,0)) | C135: =INDEX(P$133:P$138,MATCH(E135,$R$133:$R$138,0)) -> 100 | D135: =INDEX(Q$133:Q$138,MATCH(E135,$R$133:$R$138,0)) -> 最高100 | E135: 3 | F135: =INDEX(S$133:S$138,MATCH(E135,$R$133:$R$138,0)) -> 30 | N135: 园区 | O135: =IF(ISNUMBER(政策金额数据!E34),政策金额数据!E34,"") -> 100 | P135: =IF(ISNUMBER(政策金额数据!F34),政策金额数据!F34,"") -> 150 | Q135: =政策金额数据!G34 -> 100—150 | R135: =COUNTIFS($P$133:$P$138,"<"&P135)+COUNTIFS($P$133:P135,P135) -> 5 | S135: 29
A136: =INDEX(N$133:N$138,MATCH(E136,$R$133:$R$138,0)) -> 相城 | B136: =INDEX(O$133:O$138,MATCH(E136,$R$133:$R$138,0)) | C136: =INDEX(P$133:P$138,MATCH(E136,$R$133:$R$138,0)) -> 100 | D136: =INDEX(Q$133:Q$138,MATCH(E136,$R$133:$R$138,0)) -> 最高100 | E136: 4 | F136: =INDEX(S$133:S$138,MATCH(E136,$R$133:$R$138,0)) -> 32 | N136: 高新区 | O136: =IF(ISNUMBER(政策金额数据!E35),政策金额数据!E35,"") | P136: =IF(ISNUMBER(政策金额数据!F35),政策金额数据!F35,"") -> 100 | Q136: =政策金额数据!G35 -> 最高100 | R136: =COUNTIFS($P$133:$P$138,"<"&P136)+COUNTIFS($P$133:P136,P136) -> 3 | S136: 30
A137: =INDEX(N$133:N$138,MATCH(E137,$R$133:$R$138,0)) -> 园区 | B137: =INDEX(O$133:O$138,MATCH(E137,$R$133:$R$138,0)) -> 100 | C137: =INDEX(P$133:P$138,MATCH(E137,$R$133:$R$138,0)) -> 150 | D137: =INDEX(Q$133:Q$138,MATCH(E137,$R$133:$R$138,0)) -> 100—150 | E137: 5 | F137: =INDEX(S$133:S$138,MATCH(E137,$R$133:$R$138,0)) -> 29 | N137: 吴江 | O137: =IF(ISNUMBER(政策金额数据!E36),政策金额数据!E36,"") -> 50 | P137: =IF(ISNUMBER(政策金额数据!F36),政策金额数据!F36,"") -> 150 | Q137: =政策金额数据!G36 -> 50 / 100 / 150 | R137: =COUNTIFS($P$133:$P$138,"<"&P137)+COUNTIFS($P$133:P137,P137) -> 6 | S137: 31
A138: =INDEX(N$133:N$138,MATCH(E138,$R$133:$R$138,0)) -> 吴江 | B138: =INDEX(O$133:O$138,MATCH(E138,$R$133:$R$138,0)) -> 50 | C138: =INDEX(P$133:P$138,MATCH(E138,$R$133:$R$138,0)) -> 150 | D138: =INDEX(Q$133:Q$138,MATCH(E138,$R$133:$R$138,0)) -> 50 / 100 / 150 | E138: 6 | F138: =INDEX(S$133:S$138,MATCH(E138,$R$133:$R$138,0)) -> 31 | N138: 相城 | O138: =IF(ISNUMBER(政策金额数据!E37),政策金额数据!E37,"") | P138: =IF(ISNUMBER(政策金额数据!F37),政策金额数据!F37,"") -> 100 | Q138: =政策金额数据!G37 -> 最高100 | R138: =COUNTIFS($P$133:$P$138,"<"&P138)+COUNTIFS($P$133:P138,P138) -> 4 | S138: 32

Sheet 兑现与现金流
A2: 兑现条件与分期现金流
A3: 首期金额仅对文档明确的现行比例计算；各节点均以签约、考核和审核为前提。
A5: 地区 | B5: 资金类型 | C5: 比例或方式 | D5: 触发及周期 | E5: 版本/到账边界 | F5: 住房兑现方式 | G5: 住房期限与关键条件 | H5: 互斥及衔接 | I5: 来源
A6: 吴中（东吴） | B6: 项目 | C6: 50% / 30% / 20% | D6: 立项签约；一般满1年中期；一般满3年验收 | E6: 比例明确；考核通过后拨，非固定到账日 | F6: 购房按年度，比例年限待2026通知；旧4:3:3不能移用 | G6: 新细则50—200万，创业/团队旧档与新范围存在冲突 | H6: 房票50万与购房就高；租购不重复、按规则补差 | I6: 东吴领军人才政策(4).docx B38—68
A7: 姑苏区（区级） | B7: 创业扶持 | C7: 分期；比例未列 | D7: 签合同后依进度兑现；中期、结题监督 | E7: 不得把立项日视为到账日 | F7: 住房补贴比例、发放周期未列 | G7: 创业领军最高100；孵化/创新最高50；市区含吴江购房 | H7: 市区同类住房衔接待核；租购不重复 | I7: 姑苏区领军人才政策(1).docx B18—34、B79—93
A8: 常熟（昆承） | B8: 综合扶持/常规 | C8: 现行未确认 | D8: 待落户资格保留1年；创业落户并考察，创新入职 | E8: 2020旧4:3:3单列历史，不用于2026预算 | F8: 房票2025上限150、最高房款40%；2026细则待核 | G8: 传统安家旧房款60%与房票40%不同制度，不能相加 | H8: 房票与传统安家互抵、适用批次需书面确认 | I8: 常熟市昆承英才科技创新创业领军人才计划_2026(1).docx B21—42
A9: 昆山 | B9: 项目 | C9: 文档列重大70/30；一般50/50 | D9: 立项与验收两期；中期仍需检查 | E9: 引用混有2024/2021文件；2026比例须对新细则核验 | F9: 购房款50%；个人最高60、团队100；上级累计200；分期未明 | G9: 认定日起5年内新购；市区镇1:1是财政分担 | H9: 房票为对应补贴60%，且≤房款30%；与购房补贴二选一 | I9: 昆山双创(2).docx B42—79、B136、B150—162
A10: 工业园区（金鸡湖） | B10: 启动/综合补贴 | C10: 常规分期未列比例；成长80万达条件一次性 | D10: 一般立项后1年内签约；省外专项6个月；后续考核 | E10: 旧启动指南依据2021版本，不直接作为2026比例 | F10: 常规100—150万；分3年/3次，各次申请间隔≥12个月，比例未列 | G10: 重大200、成长150；2026购房起算细则须看协议 | H10: 同类从新、从优、从高，不直接全额累加 | I10: 金鸡湖科技领军人才创新创业工程专题介绍(2).docx B26—41、B82
A11: 高新区 | B11: 项目 | C11: 统一分期比例未核实 | D11: 立项后6个月内签约；到账周期未列 | E11: 财政7:3为政府分担，绝非首尾款70/30 | F11: 创业最高100、创新50；立项3年内区内购房；比例未列 | G11: 3年购房资格期不等于分3年拨款 | H11: 省市区同类支持从高不重复 | I11: 苏州高新区科技创新创业领军人才计划专题介绍_2026(2).docx B26—42、B80
A12: 吴江 | B12: 科研经费 | C12: 新版分期比例未列 | D12: 项目期与中期验收节点须看新合同 | E12: 2021旧50/30/20不可移用2025新版 | F12: 人才房票；人才使用后房企结算，非直接给人才现金 | G12: 房票发放日起12个月且政策执行期内；2025/10/24起试行1年 | H12: 领房票次月停租贴、扣减已享；一人一票；夫妻可合用 | I12: 苏州吴江区创新创业领军人才计划专题介绍_2026(2).docx B27—42
A13: 相城 | B13: 项目/安家 | C13: 项目按年未列比例；现金安家50/50 | D13: 一般立项1年后中期；验收后余款 | E13: 房票修订最高50万，团队150的半数不能推作75万房票 | F13: 首笔现金：次年起、中期通过、唯一自住；二笔：交房产权＋验收 | G13: 房票立项后3个月提出需求；每月集中；有效12个月 | H13: 房票纳入安家，不额外累加；50万限额衔接部分待核 | I13: 相城区科技领军人才计划(1).docx B30—46
A17: 东吴常规创业：100—300万元资助的分期示意
A18: 横轴为兑现节点，不是等间隔年份；中期一般满1年后，验收一般满3年后，均不承诺固定到账日。
A20: 兑现节点 | B20: 本期比例 | C20: 累计比例 | D20: 100万档累计 | E20: 300万档累计 | F20: 考核条件
A21: 立项签约 | B21: 0.5 | C21: =SUM(B$21:B21) -> 0.5 | D21: =C21*政策金额数据!E6 -> 50 | E21: =C21*政策金额数据!F6 -> 150 | F21: 满足立项、合同等条件
A22: 中期通过 | B22: 0.3 | C22: =SUM(B$21:B22) -> 0.8 | D22: =C22*政策金额数据!E6 -> 80 | E22: =C22*政策金额数据!F6 -> 240 | F22: 一般项目一年期满后检查
A23: 验收通过 | B23: 0.2 | C23: =SUM(B$21:B23) -> 1 | D23: =C23*政策金额数据!E6 -> 100 | E23: =C23*政策金额数据!F6 -> 300 | F23: 一般项目三年期满后验收
A43: 本期金额测算
A45: 节点 | B45: 本期100万档 | C45: 本期300万档 | D45: 说明
A46: 立项签约 | B46: =B21*政策金额数据!E6 -> 50 | C46: =B21*政策金额数据!F6 -> 150 | D46: 不能视为申报后立即到账
A47: 中期通过 | B47: =B22*政策金额数据!E6 -> 30 | C47: =B22*政策金额数据!F6 -> 90 | D47: 检查暂缓则拨款暂缓
A48: 验收通过 | B48: =B23*政策金额数据!E6 -> 20 | C48: =B23*政策金额数据!F6 -> 60 | D48: 未通过可能终止尾款与相关待遇

Sheet 申报条件与流程
A2: 申报门槛、窗口与流程
A3: 基础条件不是获评保证；具体引进日期、系统入口和受理时点需对应当批通知。
A5: 地区 | B5: 创业学历 | C5: 创业经历 | D5: 个人基础实缴（万元） | E5: 创业股权要求 | F5: 出资/资本补充条件 | G5: 企业及在地要求 | H5: 创新人才条件 | I5: 团队规模与投入 | J5: 附件列示受理窗口 | K5: 流程 | L5: 入口/咨询 | M5: 来源
A6: 吴中（东吴） | B6: 本科 | C6: ≥3年 | D6: 100 | E6: ≥20%或最大自然人股东 | F6: 持股公司≥200万 | G6: 企业≤2年；≥2名参保员工 | H6: 博士；相关经历≥2年；年薪≥30万；全职≥3年 | I6: ≥3人；投入有冲突：总览3年≥3000万，流程总≥1亿且已≥3000万 | J6: 2026首批4/2—5/6；常年受理、集中评审 | K6: 注册填报→属地推荐→形式及背景审查→专家/答辩/考察→审议公示→合同 | L6: http://222.92.64.216:9090/home | M6: 东吴领军人才政策(4).docx B05—09、B18、B28/80、B73—124
A7: 姑苏区（区级） | B7: 原则硕士 | C7: ≥3年 | D7: 100 | E7: ≥30%或自然人第一大股东 | F7: 领军注册资本≥500万；孵化≥300万（非个人实缴） | G7: 获称号2年内总部设区；2025批次时点不能移用 | H7: 博士，特定人才可硕士；≥2年；年薪≥30万；全职≥3年 | I7: 文档未列独立团队完整门槛 | J7: 2026月历7—8月指引；完整批次未提供 | K7: 注册激活→填报→街道初审→形式审查→专家/考察→公示审定→三方合同 | L7: 文档未提供明确网址 | M7: 姑苏区领军人才政策(1).docx B09、B12、B39—60
A8: 常熟（昆承） | B8: 本科 | C8: 原则≥3年 | D8: 100 | E8: 通常≥30%；特定条件可≥20% | F8: 持股平台须穿透折算 | G8: 至少2名非股东员工参保；批次落地时点分别核对 | H8: 博士；相关关键岗位≥5年；一般年薪≥36万；全职≥3年 | I8: ≥3人；已投入≥3000万或融资≥2000万；立项后3年投入≥5000万 | J8: 首批4/1—4/30；二批9/15—9/30为第三方转述；团队全年 | K8: 虞企通→板块推荐→资格/技术/实地/面试/综合评审→审议公示→合同→兑现 | L8: https://zrk.changshu.gov.cn | M8: 常熟市昆承英才科技创新创业领军人才计划_2026(1).docx B09、B14—18、B46—60
A9: 昆山 | B9: 本科 | C9: ≥3年 | D9: 100 | E9: ≥20%或自然人第一大股东 | F9: 持股公司≥200万；省外专项个人≥300万/平台≥600万 | G9: 企业≥2名参保员工；2026通知列具体成立窗口 | H9: 一般博士；≥2年；年薪≥30万；全职≥3年 | I9: ≥4人；总投入≥2000万、前期≥1000万；5年产业化 | J9: 2026 5/1—5/30；未落户常年、定期评审 | K9: 昆如意注册→一企一档/个人→填报材料→区镇推荐→分类评审→认定合同→检查验收 | L9: http://180.97.207.63:8099 | M9: 昆山双创(2).docx B04—39、B83—85
A10: 工业园区（金鸡湖） | B10: 本科 | C10: ≥3年；博士折算3年 | D10: 100 | E10: 通常≥30%或第一大自然人股东 | F10: 企业基本实缴≥100万；300万档企业实缴≥300万 | G10: 董事长/总经理/执行事务董事；入选至验收个人出资不减 | H10: 博士或正高；2026≥2年；年薪≥30万；全职≥3年 | I10: 重大创业类别另评，不替代独立团队资格 | J10: 首批截止4/10；二批截止8/20；均为2026 | K10: 官网注册→填报→招商与科创委审核→网评/答辩→公示发文→落地签约 | L10: http://techpioneers.sipac.gov.cn/ | M10: 金鸡湖科技领军人才创新创业工程专题介绍(2).docx B15—21、B31、B46—63
A11: 高新区 | B11: 本科 | C11: ≥3年；博士折算3年 | D11: 100 | E11: ≥20%或第一大自然人股东 | F11: 200万经费需个人实缴≥300万；300万经费需≥500万 | G11: 持股公司≥200万；出资股权等可签约前达标 | H11: 一般博士；≥2年；年薪≥30万；全职≥3年 | I11: ≥3人；重点总≥3000万/目前≥500万；顶尖总≥1亿/目前≥3000万 | J11: 首批截止2/28；二批延期至9/15（2026） | K11: 平台→板块初审→科创局复核→评审审议→公示→立项6个月内签约 | L11: 文档内“网上入口”链接见原文索引 | M11: 苏州高新区科技创新创业领军人才计划专题介绍_2026(2).docx B16—21、B48—66
A12: 吴江 | B12: 本科 | C12: ≥3年 | D12: 100 | E12: ≥20%或自然人第一大股东 | F12: 持股公司≥200万等附加条件 | G12: 每年企业工作≥6个月；2026答问具体落地日期须对批次 | H12: 一般博士；年薪≥30万；全职服务≥3年 | I12: ≥3人；总投入≥1亿；已投/融资≥2000万或上年销售>2000万 | J12: 2026月历8—9月指引；准确受理时点待核 | K12: 属地推荐→形式→网评→资格→答辩→考察→审议公示→正式合同 | L12: 向区科技领军服务中心确认：0512-63981898 | M12: 苏州吴江区创新创业领军人才计划专题介绍_2026(2).docx B15—22、B45—55
A13: 相城 | B13: 硕士 | C13: 丰富经历；未定统一年数 | D13: 100 | E13: ≥30%或第一大自然人股东且≥20% | F13: 青年创业个人实缴≥50万 | G13: 主要精力在相城；近年具体日期看批次 | H13: 博士；年薪≥上年苏州指定统计工资的2倍；全职≥3年 | I13: ≥3人；3年总投资≥3000万；5年产业化 | J13: 细则上下半年两批；2026月历8—9月指引 | K13: 网上→属地推荐→专家→考察→部门审议→公示7天→政府审定→合同 | L13: 向区科技局确认：0512-85182157 | M13: 相城区科技领军人才计划(1).docx B16—25、B51—56
A17: 门槛排序解读
A19: 个人基础实缴均为100万元，无金额高低差别；相城青年50万元是另一类别，不替换普通创业门槛。
A21: 学历按本科、硕士排序：本科为吴中/常熟/昆山/园区/高新区/吴江；硕士为姑苏区（原则）/相城（可评估放宽）。
A23: 创新固定年薪门槛：多数≥30万元，常熟一般≥36万元；相城为上年度指定统计工资2倍，缺基数不换算为固定金额。
A25: 团队人数：吴中/常熟/高新区/吴江/相城至少3人，昆山至少4人；姑苏区和园区材料未给同口径独立团队要求。
A27: 基础实缴、企业注册资本、项目总投入及前期投入是四种不同指标，禁止直接混排。

Sheet 配套与住房
A2: 配套工具、住房条件与雷达图
A3: 贷款须偿还，股权投资涉及交易安排，均不并入财政无偿资助；空白表示附件未给出可比现行额度。
A5: 地区 | B5: 常规办公面积上限㎡ | C5: 支持年限 | D5: 企业贷款上限万元 | E5: 股权投资上限万元 | F5: 常规贴息上限万元 | G5: 上级叠加规则 | H5: 生活与企业服务 | I5: 适用限制及补充 | J5: 来源
A6: 吴中（东吴） | B6: 1000 | C6: 3 | D6: 1000 | E6: 1000 | F6: 30 | G6: 项目上级国家/省1:1，市级区承担不抵扣；住房就高 | H6: 子女就近统筹、医疗体检、人才卡；资格依认定 | I6: 住房1500元/月≤3年为过渡；房票50与安家互抵 | J6: 东吴领军人才政策(4).docx B49、B154—177
A7: 姑苏区（区级） | G7: 上级创业项目追加最高200万；非自动累计 | H7: 人才礼遇卡、礼遇通；市级服务须分类审核 | I7: 办公补贴≤30万；文内C类对应与自动享受表述需另核 | J7: 姑苏区领军人才政策(1).docx B18、B28、B74—93
A8: 常熟（昆承） | G8: 本市/跨区重复申报限制；就高补差须依新合同 | H8: 伙伴计划、一站式、教育医疗；驿站、公寓各有资格 | I8: 旧贷款5000/贴息30等不作2026现行数据 | J8: 常熟市昆承英才科技创新创业领军人才计划_2026(1).docx B79—85
A9: 昆山 | C9: 1 | D9: 1500 | E9: 1000 | G9: 国家、省可累计；苏州级就高不重复，2026原文待核 | H9: 公共秘书、昆才优享、教育医疗、算力与产业对接 | I9: 免费工位最长12个月；人才房票与购房二选一 | J9: 昆山双创(2).docx B57、B122—148
A10: 工业园区（金鸡湖） | B10: 500 | C10: 3 | D10: 3000 | F10: 150 | G10: 省双创1:1；国家生活补助最高1:1.5；同类就高 | H10: 领军启航/伙伴；教育、医疗、随迁另核条件 | I10: 常规场地500㎡；重大5000、成长1000㎡；平台补贴3年累计50万 | J10: 金鸡湖科技领军人才创新创业工程专题介绍(2).docx B75—82
A11: 高新区 | D11: 2000 | E11: 500 | F11: 30 | G11: 同时省市区从高不重复；省团队1:1最高500等 | H11: 高层次人才服务卡；苏新乐居；教育医疗与市卡分类 | I11: 服务卡身份不是自动市级C类；文档未列场地面积 | J11: 苏州高新区科技创新创业领军人才计划专题介绍_2026(2).docx B80—85
A12: 吴江 | G12: 区省市分别申报；配套和补差不直接累加 | H12: 人才公寓、研发办公、家属子女、投融资与产学研 | I12: 科贷通全区31.18亿元不是人才个人额度 | J12: 苏州吴江区创新创业领军人才计划专题介绍_2026(2).docx B65、B69—78
A13: 相城 | B13: 200 | C13: 3 | D13: 1000 | G13: 市级项目区承担可叠加；国家省1:1；安家就高 | H13: 相才汇、英才卡、教育医疗；学费≤4万/年、体检≤4000元按资格 | I13: 团队办公500㎡；中试2000㎡1年；相才贷个人200万与企业贷款分列 | J13: 相城区科技领军人才计划(1).docx B72—82
A17: 四地常规额度画像
A18: 雷达值=本地上限÷图中四地该维度最高值；仅比较金额，不加权、不求总分。常熟缺额、吴中住房冲突、园区综合口径、姑苏区无独立团队，未入雷达。
A20: 维度 | B20: 昆山 | C20: 高新区 | D20: 吴江 | E20: 相城 | F20: 四地最大值
A21: 创业经费 | B21: =政策金额数据!F9 -> 400 | C21: =政策金额数据!F11 -> 300 | D21: =政策金额数据!F12 -> 300 | E21: =政策金额数据!F13 -> 100 | F21: =MAX(B21:E21) -> 400
A22: 企业创新经费 | B22: =政策金额数据!F17 -> 200 | C22: =政策金额数据!F19 -> 100 | D22: =政策金额数据!F20 -> 150 | E22: =政策金额数据!F21 -> 100 | F22: =MAX(B22:E22) -> 200
A23: 常规团队经费 | B23: =政策金额数据!F25 -> 1000 | C23: =政策金额数据!F27 -> 600 | D23: =政策金额数据!F28 -> 1000 | E23: =政策金额数据!F29 -> 800 | F23: =MAX(B23:E23) -> 1000
A24: 创业住房 | B24: =政策金额数据!F33 -> 60 | C24: =政策金额数据!F35 -> 100 | D24: =政策金额数据!F36 -> 150 | E24: =政策金额数据!F37 -> 100 | F24: =MAX(B24:E24) -> 150
A27: 归一化维度 | B27: 昆山 | C27: 高新区 | D27: 吴江 | E27: 相城
A28: 创业经费 | B28: =B21/$F21 -> 1 | C28: =C21/$F21 -> 0.75 | D28: =D21/$F21 -> 0.75 | E28: =E21/$F21 -> 0.25
A29: 企业创新经费 | B29: =B22/$F22 -> 1 | C29: =C22/$F22 -> 0.5 | D29: =D22/$F22 -> 0.75 | E29: =E22/$F22 -> 0.5
A30: 常规团队经费 | B30: =B23/$F23 -> 1 | C30: =C23/$F23 -> 0.6 | D30: =D23/$F23 -> 1 | E30: =E23/$F23 -> 0.8
A31: 创业住房 | B31: =B24/$F24 -> 0.4 | C31: =C24/$F24 -> 0.66666667 | D31: =D24/$F24 -> 1 | E31: =E24/$F24 -> 0.66666667
A54: 企业贷款额度由少到多（融资工具，万元）
A56: 地区 | B56: 上限
A57: 吴中 | B57: =D6 -> 1000
A58: 相城 | B58: =D13 -> 1000
A59: 昆山 | B59: =D9 -> 1500
A60: 高新区 | B60: =D11 -> 2000
A61: 园区 | B61: =D10 -> 3000
A83: 住房比较的共同检查项
A85: 核定额度与房价比例 → 区域/新房限制 → 唯一住房或产权份额 → 购房与房票有效期 → 考核条件 → 租贴抵扣 → 财政结算对象。
A87: 吴江房票给房企结算；相城房票可抵首付且纳入安家；昆山房票为对应补贴60%且最高房款30%；常熟2025房票最高房款40%，2026衔接待核。

Sheet 历史数据与边界
A2: 历史申报及立项数据
A3: 按地区保留原始年份、批次、阶段、单位和来源等级；不制作不具可比性的八地通过率/年度总量排名。
A5: 地区 | B5: 年度/披露年 | C5: 批次或期间 | D5: 结果阶段 | E5: 文档数量/边界值 | F5: 同口径申报数 | G5: 单位 | H5: 统计范围 | I5: 证据属性 | J5: 来源定位 | K5: 解释和限制 | L5: 局部数量之比
A6: 吴中（东吴） | B6: 2023 | C6: 全年 | D6: 正式立项 | E6: 103 | G6: 项目 | H6: 东吴区级 | I6: 官方披露（按文档） | J6: 东吴领军人才政策(4).docx B131 | K6: 不能与2025单批算年度增速 | L6: =IF(AND(ISNUMBER(E6),ISNUMBER(F6)),E6/F6,"")
A7: 吴中（东吴） | B7: 2022 | C7: 全年 | D7: 反推约数 | E7: 83 | G7: 项目 | H7: 东吴区级 | I7: 由103/1.241反推 | J7: 东吴领军人才政策(4).docx B131 | K7: 非官方直接数；不作精确趋势 | L7: =IF(AND(ISNUMBER(E7),ISNUMBER(F7)),E7/F7,"")
A8: 吴中（东吴） | B8: 2024 | C8: 全年 | D8: 目标下限 | E8: 100 | G8: 项目 | H8: 东吴区级 | I8: 目标“超100” | J8: 东吴领军人才政策(4).docx B128、131 | K8: 非完成实绩 | L8: =IF(AND(ISNUMBER(E8),ISNUMBER(F8)),E8/F8,"")
A9: 吴中（东吴） | B9: 2025 | C9: 第二批 | D9: 拟立项 | E9: 47 | F9: 77 | G9: 项目 | H9: 东吴区级 | I9: 第三方清点；日期混排 | J9: 东吴领军人才政策(4).docx B143—147 | K9: 可算47/77描述比例，非2026个人成功率 | L9: =IF(AND(ISNUMBER(E9),ISNUMBER(F9)),E9/F9,"") -> 0.61038961
A10: 姑苏区（区级） | B10: 2023 | C10: 第一批 | D10: 拟认定 | E10: 12 | G10: 项目 | H10: 姑苏区级 | I10: 文档称已核实 | J10: 姑苏区领军人才政策(1).docx B65 | K10: 缺第二批 | L10: =IF(AND(ISNUMBER(E10),ISNUMBER(F10)),E10/F10,"")
A11: 姑苏区（区级） | B11: 2024 | C11: 第一批 | D11: 拟认定 | E11: 10 | G11: 项目 | H11: 姑苏区级 | I11: 文档称已核实 | J11: 姑苏区领军人才政策(1).docx B65 | K11: 缺第二批 | L11: =IF(AND(ISNUMBER(E11),ISNUMBER(F11)),E11/F11,"")
A12: 姑苏区（区级） | B12: 2025 | C12: 公示批次 | D12: 拟认定 | E12: 20 | G12: 项目 | H12: 姑苏区级 | I12: 名单全文口径 | J12: 姑苏区领军人才政策(1).docx B65 | K12: 三个已知批次合42，不是四批也非三年完整总数 | L12: =IF(AND(ISNUMBER(E12),ISNUMBER(F12)),E12/F12,"")
A13: 常熟（昆承） | B13: 2025 | C13: 第二批 | D13: 拟立项 | E13: 86 | G13: 项目 | H13: 常熟本级 | I13: 公示转载名单 | J13: 常熟市昆承英才科技创新创业领军人才计划_2026(1).docx B68—73 | K13: 创业43、创新10、待落户24、大赛9 | L13: =IF(AND(ISNUMBER(E13),ISNUMBER(F13)),E13/F13,"")
A14: 常熟（昆承） | B14: 2024 | C14: 梅李镇全年 | D14: 获评 | E14: 1 | F14: 6 | G14: 项目 | H14: 镇域 | I14: 文档引镇概况 | J14: 常熟市昆承英才科技创新创业领军人才计划_2026(1).docx B68、76 | K14: 1/6仅镇域比例 | L14: =IF(AND(ISNUMBER(E14),ISNUMBER(F14)),E14/F14,"") -> 0.16666667
A15: 常熟（昆承） | B15: 2024 | C15: 常熟高新区全年 | D15: 获评 | E15: 46 | G15: 项目 | H15: 板块 | I15: 官方报道（按文档） | J15: 常熟市昆承英才科技创新创业领军人才计划_2026(1).docx B68 | K15: 不能代表全市 | L15: =IF(AND(ISNUMBER(E15),ISNUMBER(F15)),E15/F15,"")
A16: 昆山 | B16: 2023 | C16: 全年 | D16: 入选 | E16: 128 | G16: 人才 | H16: 昆山市本级 | I16: 来源标签不完整 | J16: 昆山双创(2).docx B94 | K16: 75%等结构占比缺可追溯明细 | L16: =IF(AND(ISNUMBER(E16),ISNUMBER(F16)),E16/F16,"")
A17: 昆山 | B17: 2024 | C17: 全年 | D17: 新增 | E17: 250 | G17: 人才/团队 | H17: 各层级合计 | I17: 来源标签不完整 | J17: 昆山双创(2).docx B101 | K17: 不与市本级128相比 | L17: =IF(AND(ISNUMBER(E17),ISNUMBER(F17)),E17/F17,"")
A18: 昆山 | B18: 2025 | C18: 全年 | D18: 新增 | E18: 180 | G18: 人才/团队 | H18: 各层级合计 | I18: 来源标签不完整 | J18: 昆山双创(2).docx B110 | K18: 不作2026本级获评量 | L18: =IF(AND(ISNUMBER(E18),ISNUMBER(F18)),E18/F18,"")
A19: 昆山 | B19: 2024 | C19: 第二批 | D19: 约数/反推 | E19: 71 | G19: 项目 | H19: 昆山市本级 | I19: 29/40.85%反推附近值 | J19: 昆山双创(2).docx B104 | K19: 非精确名单计数 | L19: =IF(AND(ISNUMBER(E19),ISNUMBER(F19)),E19/F19,"")
A20: 工业园区（金鸡湖） | B20: 2024 | C20: 18届第一批 | D20: 现场评审 | E20: 440 | G20: 项目 | H20: 园区工程 | I20: 官方新闻（按文档） | J20: 金鸡湖科技领军人才创新创业工程专题介绍(2).docx B67 | K20: 申报近1000，不计算精确通过率 | L20: =IF(AND(ISNUMBER(E20),ISNUMBER(F20)),E20/F20,"")
A21: 工业园区（金鸡湖） | B21: 2025 | C21: 18届新闻披露 | D21: 入围 | E21: 359 | G21: 项目 | H21: 园区工程 | I21: 官方新闻（按文档） | J21: 金鸡湖科技领军人才创新创业工程专题介绍(2).docx B67 | K21: 披露年2025不代表项目年度2025；非正式立项 | L21: =IF(AND(ISNUMBER(E21),ISNUMBER(F21)),E21/F21,"")
A22: 工业园区（金鸡湖） | B22: 2026 | C22: 20届第一批 | D22: 申报下限 | E22: 700 | G22: 项目 | H22: 园区工程 | I22: 原文“超700” | J22: 金鸡湖科技领军人才创新创业工程专题介绍(2).docx B67 | K22: 面试200余，不作精确比例 | L22: =IF(AND(ISNUMBER(E22),ISNUMBER(F22)),E22/F22,"")
A23: 工业园区（金鸡湖） | B23: 2026 | C23: 截至6月 | D23: 累计引进下限 | E23: 3600 | G23: 人才 | H23: 园区工程累计 | I23: 原文“超3600” | J23: 金鸡湖科技领军人才创新创业工程专题介绍(2).docx B70 | K23: 非年度立项 | L23: =IF(AND(ISNUMBER(E23),ISNUMBER(F23)),E23/F23,"")
A24: 高新区 | B24: 2024 | C24: 全年 | D24: 正式立项 | E24: 131 | G24: 项目 | H24: 高新区区级 | I24: 官方公报（按文档） | J24: 苏州高新区科技创新创业领军人才计划专题介绍_2026(2).docx B71 | K24: 缺全量申报分母 | L24: =IF(AND(ISNUMBER(E24),ISNUMBER(F24)),E24/F24,"")
A25: 高新区 | B25: 2025 | C25: 第一批 | D25: 正式立项 | E25: 103 | G25: 项目 | H25: 高新区区级 | I25: 来源高新区的协会转载 | J25: 苏州高新区科技创新创业领军人才计划专题介绍_2026(2).docx B71 | K25: 光子12是子集，不另加 | L25: =IF(AND(ISNUMBER(E25),ISNUMBER(F25)),E25/F25,"")
A26: 吴江 | B26: 2024 | C26: 第一批/30批 | D26: 正式立项 | E26: 36 | G26: 项目 | H26: 吴江区级 | I26: 正式通知（按文档） | J26: 苏州吴江区创新创业领军人才计划专题介绍_2026(2).docx B59 | K26: 不可与第二批拟立项合成全年正式数 | L26: =IF(AND(ISNUMBER(E26),ISNUMBER(F26)),E26/F26,"")
... A30: 相城 | B30: 2025 | C30: 全年通知 | D30: 正式认定 | E30: 35 | G30: 团队+人才 | H30: 相城区级 | I30: 正式通知转载 | J30: 相城区科技领军人才计划(1).docx B60—65 | K30: 1团队+34人才；拟名单创业27创新7 | L30: =IF(AND(ISNUMBER(E30),ISNUMBER(F30)),E30/F30,"")
A34: 可计算但不能泛化的比例
A36: 东吴2025第二批47/77=61.04%（第三方、日期有混排）；常熟梅李2024获评1/申报6=16.67%（仅镇域）。
A38: 这些比例没有相同地区、年度、类别与审核标准，不可比较成“哪个地区更容易”。
A41: 常熟2025第二批拟立项结构
A43: 类别 | B43: 拟立项数 | C43: 占比
A44: 创业已落户 | B44: 43 | C44: =B44/$B$48 -> 0.5
A45: 创新 | B45: 10 | C45: =B45/$B$48 -> 0.11627907
A46: 创业待落户 | B46: 24 | C46: =B46/$B$48 -> 0.27906977
A47: 创业待落户大赛 | B47: 9 | C47: =B47/$B$48 -> 0.10465116
A48: 合计 | B48: =SUM(B44:B47) -> 86 | C48: =B48/$B$48 -> 1
A50: 上表86项中，待落户与大赛共33项，仍需落实后续落地条件。来源：常熟文档B71—73。

Sheet 政策金额数据
A2: 政策金额原始输入
A3: 金额单位：万元人民币。空白=未明确/不适用；真实零仅用于姑苏区创新项目经费。未另行联网核验。
A5: 编号 | B5: 地区 | C5: 类别 | D5: 子类 | E5: 最低/最低档 | F5: 最高/最高档 | G5: 原文档次 | H5: 资金性质 | I5: 适用及证据边界 | J5: 附件来源 | K5: 原文块定位 | L5: 区间跨度
A6: P01 | B6: 吴中（东吴） | C6: 创业 | D6: 常规项目 | E6: 100 | F6: 300 | G6: 100—300 | H6: 项目经费 | I6: 现行文档口径 | J6: 东吴领军人才政策(4).docx | K6: B11 | L6: =IF(AND(ISNUMBER(E6),ISNUMBER(F6)),F6-E6,"") -> 200
A7: P02 | B7: 姑苏区（区级） | C7: 创业 | D7: 领军类 | F7: 100 | G7: 最高100 | H7: 创业扶持 | I7: 2021办法＋2025通知；2026批次待核 | J7: 姑苏区领军人才政策(1).docx | K7: B18 | L7: =IF(AND(ISNUMBER(E7),ISNUMBER(F7)),F7-E7,"")
A8: P03 | B8: 常熟（昆承） | C8: 创业 | D8: 常规已落户 | G8: 未确认 | H8: 项目经费 | I8: 2025新细则完整资金条款缺失 | J8: 常熟市昆承英才科技创新创业领军人才计划_2026(1).docx | K8: B24—26 | L8: =IF(AND(ISNUMBER(E8),ISNUMBER(F8)),F8-E8,"")
A9: P04 | B9: 昆山 | C9: 创业 | D9: 领军类 | E9: 100 | F9: 400 | G9: 100 / 200 / 300 / 400 | H9: 项目经费 | I9: 文档列2026额度 | J9: 昆山双创(2).docx | K9: B47—52 | L9: =IF(AND(ISNUMBER(E9),ISNUMBER(F9)),F9-E9,"") -> 300
A10: P05 | B10: 工业园区（金鸡湖） | C10: 创业 | D10: 常规领军 | E10: 100 | F10: 300 | G10: 100或300（非连续档） | H10: 启动资金 | I10: 2026第二批 | J10: 金鸡湖科技领军人才创新创业工程专题介绍(2).docx | K10: B7、26 | L10: =IF(AND(ISNUMBER(E10),ISNUMBER(F10)),F10-E10,"") -> 200
A11: P06 | B11: 高新区 | C11: 创业 | D11: 常规领军 | E11: 100 | F11: 300 | G11: 100 / 200 / 300 | H11: 项目经费 | I11: 2026口径；较高档另有实缴门槛 | J11: 苏州高新区科技创新创业领军人才计划专题介绍_2026(2).docx | K11: B10、16 | L11: =IF(AND(ISNUMBER(E11),ISNUMBER(F11)),F11-E11,"") -> 200
A12: P07 | B12: 吴江 | C12: 创业 | D12: 常规领军 | E12: 100 | F12: 300 | G12: 100 / 200 / 300 | H12: 科研经费 | I12: 2025新版＋2026答问 | J12: 苏州吴江区创新创业领军人才计划专题介绍_2026(2).docx | K12: B6 | L12: =IF(AND(ISNUMBER(E12),ISNUMBER(F12)),F12-E12,"") -> 200
A13: P08 | B13: 相城 | C13: 创业 | D13: 常规领军 | E13: 50 | F13: 100 | G13: 50 / 100 | H13: 项目资助 | I13: 不含特别优秀上浮 | J13: 相城区科技领军人才计划(1).docx | K13: B10—12 | L13: =IF(AND(ISNUMBER(E13),ISNUMBER(F13)),F13-E13,"") -> 50
A14: P09 | B14: 吴中（东吴） | C14: 创新 | D14: 个人 | E14: 50 | F14: 100 | G14: 50—100 | H14: 项目经费 | I14: 现行文档口径 | J14: 东吴领军人才政策(4).docx | K14: B21 | L14: =IF(AND(ISNUMBER(E14),ISNUMBER(F14)),F14-E14,"") -> 50
A15: P10 | B15: 姑苏区（区级） | C15: 创新 | D15: 个人 | E15: 0 | F15: 0 | G15: 无项目资助 | H15: 项目经费 | I15: 真实零；另有企业引才与住房补贴 | J15: 姑苏区领军人才政策(1).docx | K15: B24—26 | L15: =IF(AND(ISNUMBER(E15),ISNUMBER(F15)),F15-E15,"") -> 0
A16: P11 | B16: 常熟（昆承） | C16: 创新 | D16: 常规已落户 | G16: 未确认 | H16: 项目经费 | I16: 新细则完整资金条款缺失 | J16: 常熟市昆承英才科技创新创业领军人才计划_2026(1).docx | K16: B24—26 | L16: =IF(AND(ISNUMBER(E16),ISNUMBER(F16)),F16-E16,"")
A17: P12 | B17: 昆山 | C17: 创新 | D17: 企业创新 | E17: 100 | F17: 200 | G17: 100 / 200 | H17: 项目经费 | I17: 不含高校院所60万 | J17: 昆山双创(2).docx | K17: B51 | L17: =IF(AND(ISNUMBER(E17),ISNUMBER(F17)),F17-E17,"") -> 100
A18: P13 | B18: 工业园区（金鸡湖） | C18: 创新 | D18: 个人 | E18: 50 | F18: 100 | G18: 50—100 | H18: 综合补贴 | I18: 非纯项目经费；单列不作严格同口径排名 | J18: 金鸡湖科技领军人才创新创业工程专题介绍(2).docx | K18: B7、26 | L18: =IF(AND(ISNUMBER(E18),ISNUMBER(F18)),F18-E18,"") -> 50
A19: P14 | B19: 高新区 | C19: 创新 | D19: 个人 | E19: 50 | F19: 100 | G19: 50 / 100 | H19: 项目经费 | I19: 现行文档口径 | J19: 苏州高新区科技创新创业领军人才计划专题介绍_2026(2).docx | K19: B10 | L19: =IF(AND(ISNUMBER(E19),ISNUMBER(F19)),F19-E19,"") -> 50
A20: P15 | B20: 吴江 | C20: 创新 | D20: 个人 | E20: 50 | F20: 150 | G20: 50 / 100 / 150 | H20: 科研经费 | I20: 现行文档口径 | J20: 苏州吴江区创新创业领军人才计划专题介绍_2026(2).docx | K20: B6 | L20: =IF(AND(ISNUMBER(E20),ISNUMBER(F20)),F20-E20,"") -> 100
A21: P16 | B21: 相城 | C21: 创新 | D21: 个人 | E21: 50 | F21: 100 | G21: 50 / 80 / 100 | H21: 项目资助 | I21: 现行文档口径 | J21: 相城区科技领军人才计划(1).docx | K21: B10 | L21: =IF(AND(ISNUMBER(E21),ISNUMBER(F21)),F21-E21,"") -> 50
A22: P17 | B22: 吴中（东吴） | C22: 团队 | D22: 重大创新团队 | E22: 300 | F22: 1000 | G22: 300—1000 | H22: 项目资助 | I22: 投入门槛文内冲突，先核对 | J22: 东吴领军人才政策(4).docx | K22: B31、28、80 | L22: =IF(AND(ISNUMBER(E22),ISNUMBER(F22)),F22-E22,"") -> 700
A23: P18 | B23: 姑苏区（区级） | C23: 团队 | D23: 独立团队资助档 | G23: 未单列 | H23: 项目资助 | I23: 文档未提供独立团队金额表 | J23: 姑苏区领军人才政策(1).docx | K23: B3—6、18 | L23: =IF(AND(ISNUMBER(E23),ISNUMBER(F23)),F23-E23,"")
A24: P19 | B24: 常熟（昆承） | C24: 团队 | D24: 双创团队 | G24: 未确认 | H24: 项目经费 | I24: 2020旧500/800/1000不作现行数 | J24: 常熟市昆承英才科技创新创业领军人才计划_2026(1).docx | K24: B24—36 | L24: =IF(AND(ISNUMBER(E24),ISNUMBER(F24)),F24-E24,"")
A25: P20 | B25: 昆山 | C25: 团队 | D25: 创业团队 | E25: 400 | F25: 1000 | G25: 400 / 500 / 1000 | H25: 项目资助 | I25: 创新团队另列300/400 | J25: 昆山双创(2).docx | K25: B47 | L25: =IF(AND(ISNUMBER(E25),ISNUMBER(F25)),F25-E25,"") -> 600
A26: P21 | B26: 工业园区（金鸡湖） | C26: 特殊创业 | D26: 重大领军 | E26: 300 | F26: 1000 | G26: 300—1000 | H26: 启动资金 | I26: 重大创业类别，非独立团队类别 | J26: 金鸡湖科技领军人才创新创业工程专题介绍(2).docx | K26: B7、26 | L26: =IF(AND(ISNUMBER(E26),ISNUMBER(F26)),F26-E26,"") -> 700
A27: P22 | B27: 高新区 | C27: 团队 | D27: 重点创新团队 | E27: 400 | F27: 600 | G27: 400 / 500 / 600 | H27: 项目经费 | I27: 与顶尖团队1000—5000分开 | J27: 苏州高新区科技创新创业领军人才计划专题介绍_2026(2).docx | K27: B10 | L27: =IF(AND(ISNUMBER(E27),ISNUMBER(F27)),F27-E27,"") -> 200
A28: P23 | B28: 吴江 | C28: 团队 | D28: 重大创新创业团队 | E28: 300 | F28: 1000 | G28: 300 / 500 / 1000 | H28: 科研经费 | I28: 顶尖综合1亿元不并入 | J28: 苏州吴江区创新创业领军人才计划专题介绍_2026(2).docx | K28: B6、8 | L28: =IF(AND(ISNUMBER(E28),ISNUMBER(F28)),F28-E28,"") -> 700
A29: P24 | B29: 相城 | C29: 团队 | D29: 重点双创团队 | E29: 400 | F29: 800 | G29: 400 / 600 / 800 | H29: 项目资助 | I29: 现行文档口径 | J29: 相城区科技领军人才计划(1).docx | K29: B10 | L29: =IF(AND(ISNUMBER(E29),ISNUMBER(F29)),F29-E29,"") -> 400
A30: P25 | B30: 吴中（东吴） | C30: 住房 | D30: 全类别新细则范围 | E30: 50 | F30: 200 | G30: 50—200 | H30: 购房补贴 | I30: 文内新旧冲突；不分配为创业档 | J30: 东吴领军人才政策(4).docx | K30: B51—56 | L30: =IF(AND(ISNUMBER(E30),ISNUMBER(F30)),F30-E30,"") -> 150
A31: P26 | B31: 姑苏区（区级） | C31: 住房 | D31: 创业领军 | F31: 100 | G31: 最高100 | H31: 购房补贴 | I31: 孵化、创新最高50；非市级姑苏计划 | J31: 姑苏区领军人才政策(1).docx | K31: B18、24 | L31: =IF(AND(ISNUMBER(E31),ISNUMBER(F31)),F31-E31,"")
A32: P27 | B32: 常熟（昆承） | C32: 住房 | D32: 双创人才房票 | F32: 150 | G32: 最高150 | H32: 人才房票 | I32: 2025说明；2026具体档次待核 | J32: 常熟市昆承英才科技创新创业领军人才计划_2026(1).docx | K32: B39—40 | L32: =IF(AND(ISNUMBER(E32),ISNUMBER(F32)),F32-E32,"")
A33: P28 | B33: 昆山 | C33: 住房 | D33: 创业个人 | F33: 60 | G33: 最高60 | H33: 购房补贴 | I33: 购房款50%；团队最高100；上级累计200 | J33: 昆山双创(2).docx | K33: B70—75 | L33: =IF(AND(ISNUMBER(E33),ISNUMBER(F33)),F33-E33,"")
A34: P29 | B34: 工业园区（金鸡湖） | C34: 住房 | D34: 常规创业 | E34: 100 | F34: 150 | G34: 100—150 | H34: 购房补贴 | I34: 2026第二批；重大200、成长150另列 | J34: 金鸡湖科技领军人才创新创业工程专题介绍(2).docx | K34: B7、36 | L34: =IF(AND(ISNUMBER(E34),ISNUMBER(F34)),F34-E34,"") -> 50
A35: P30 | B35: 高新区 | C35: 住房 | D35: 创业个人 | F35: 100 | G35: 最高100 | H35: 购房补贴 | I35: 立项后3年内区内购房 | J35: 苏州高新区科技创新创业领军人才计划专题介绍_2026(2).docx | K35: B10、30—31 | L35: =IF(AND(ISNUMBER(E35),ISNUMBER(F35)),F35-E35,"")
A36: P31 | B36: 吴江 | C36: 住房 | D36: 创业个人 | E36: 50 | F36: 150 | G36: 50 / 100 / 150 | H36: 人才房票 | I36: 与创业项目档次对应 | J36: 苏州吴江区创新创业领军人才计划专题介绍_2026(2).docx | K36: B6、32—42 | L36: =IF(AND(ISNUMBER(E36),ISNUMBER(F36)),F36-E36,"") -> 100
A37: P32 | B37: 相城 | C37: 住房 | D37: 创业个人 | F37: 100 | G37: 最高100 | H37: 安家补贴 | I37: 房票纳入安家；房票最高50 | J37: 相城区科技领军人才计划(1).docx | K37: B10、30—35 | L37: =IF(AND(ISNUMBER(E37),ISNUMBER(F37)),F37-E37,"")
A38: P33 | B38: 姑苏区（区级） | C38: 孵化 | D38: 创业孵化 | F38: 50 | G38: 最高50 | H38: 创业扶持 | I38: 2025受理通道 | J38: 姑苏区领军人才政策(1).docx | K38: B18 | L38: =IF(AND(ISNUMBER(E38),ISNUMBER(F38)),F38-E38,"")
A39: P34 | B39: 常熟（昆承） | C39: 待落户 | D39: 创业 | E39: 160 | F39: 160 | G39: 160 | H39: 综合扶持 | I39: 资格1年；落户并考察后兑现，不拆现金 | J39: 常熟市昆承英才科技创新创业领军人才计划_2026(1).docx | K39: B21、24 | L39: =IF(AND(ISNUMBER(E39),ISNUMBER(F39)),F39-E39,"") -> 0
A40: P35 | B40: 常熟（昆承） | C40: 待落户 | D40: 创新 | E40: 40 | F40: 40 | G40: 40 | H40: 综合扶持 | I40: 资格1年；完成入职后兑现 | J40: 常熟市昆承英才科技创新创业领军人才计划_2026(1).docx | K40: B21、24 | L40: =IF(AND(ISNUMBER(E40),ISNUMBER(F40)),F40-E40,"") -> 0
A41: P36 | B41: 昆山 | C41: 孵化 | D41: 创业孵育 | E41: 60 | F41: 60 | G41: 60 | H41: 项目资助 | I41: 固定档次 | J41: 昆山双创(2).docx | K41: B49 | L41: =IF(AND(ISNUMBER(E41),ISNUMBER(F41)),F41-E41,"") -> 0
A42: P37 | B42: 昆山 | C42: 成长 | D42: 创业成长 | E42: 60 | F42: 60 | G42: 60 | H42: 项目资助 | I42: 固定档次 | J42: 昆山双创(2).docx | K42: B50 | L42: =IF(AND(ISNUMBER(E42),ISNUMBER(F42)),F42-E42,"") -> 0
...

Sheet 原文与来源索引
A2: 原文摘录与来源链接
A3: B编号=Word正文顶层段落或表格顺序（含空段落）；定位表格时按整表计一个块。网址为上传文档内嵌链接。
A5: 类型 | B5: 地区 | C5: 附件文件 | D5: 原文块/链接标题 | E5: 摘录或URL | F5: 说明
A6: 原文摘录 | B6: 吴江 | C6: 苏州吴江区创新创业领军人才计划专题介绍_2026(2).docx | D6: B6 | E6: 支持对象 | 科研经费档次 | 住房支持 | 重大创新创业团队 | 300 / 500 / 1000万元 | 核心成员50万元；领军人才150万元；顶尖人才300万元人才房票 | 创业领军人才 | 100 / 200 / 300万元 | 按项目档次50 / 100 / 150万元人才房票 | 创新领军人才 | 50 / 100 / 150万元 | 50万元人才房票 | F6: 附件内原文；非本次独立网页核验
A7: 原文摘录 | B7: 吴江 | C7: 苏州吴江区创新创业领军人才计划专题介绍_2026(2).docx | D7: B8 | E7: 出处：[3]及[4]第三部分。顶尖人才团队最高1亿元为项目综合扶持口径，不应等同于所有团队均可领取1亿元现金科研经费。房票金额须经认定和核定，不属于自动到账待遇。 | F7: 附件内原文；非本次独立网页核验
A8: 原文摘录 | B8: 吴江 | C8: 苏州吴江区创新创业领军人才计划专题介绍_2026(2).docx | D8: B32 | E8: 房票是用于在吴江购置新建商品住房的补贴凭证，遵循一人一票、专款专用。领军计划认定后取得申请资格，人才须在与房企签订意向购房合同前申请房票。区人社局核定额度，区委人才办与区住建局发放。[4：第二至四部分] | F8: 附件内原文；非本次独立网页核验
A9: 原文摘录 | B9: 吴江 | C9: 苏州吴江区创新创业领军人才计划专题介绍_2026(2).docx | D9: B42 | E9: 应分别核对“细则有效期”和“单张房票12个月使用期”。细则同时约束政策执行期内有效，因此不能仅凭12个月期限推定政策到期后仍可使用；跨届满日期的房票须取得主管部门明确办理口径。[4：第五部分，阅读提示] | F9: 附件内原文；非本次独立网页核验
A10: 内嵌链接 | B10: 吴江 | C10: 苏州吴江区创新创业领军人才计划专题介绍_2026(2).docx | D10: 查看来源 1 | E10: https://www.wujiang.gov.cn/zgwj/kjcs/202511/7a5d447af04c4ddfb1d5e87a36a45654.shtml | F10: 从附件关系文件提取；链接有效性未重新核验
A11: 内嵌链接 | B11: 吴江 | C11: 苏州吴江区创新创业领军人才计划专题介绍_2026(2).docx | D11: 查看来源 2 | E11: https://www.suzhou.gov.cn/szsrmzf/rdwd3/202601/18c9614112ac4d37b574c3a81ee28c7b.shtml | F11: 从附件关系文件提取；链接有效性未重新核验
A12: 内嵌链接 | B12: 吴江 | C12: 苏州吴江区创新创业领军人才计划专题介绍_2026(2).docx | D12: 查看来源 3 | E12: https://www.suzhou.gov.cn/szsrmzf/rdwd3/202601/a72e55feaf7b46a7b391698e4c9e890d.shtml | F12: 从附件关系文件提取；链接有效性未重新核验
A13: 内嵌链接 | B13: 吴江 | C13: 苏州吴江区创新创业领军人才计划专题介绍_2026(2).docx | D13: 查看来源 4 | E13: https://www.szwjtalent.com/PolicyD/102257.aspx | F13: 从附件关系文件提取；链接有效性未重新核验
A14: 内嵌链接 | B14: 吴江 | C14: 苏州吴江区创新创业领军人才计划专题介绍_2026(2).docx | D14: 查看来源 5 | E14: https://www.suzhou.gov.cn/szsrmzf/rdwd3/202601/8b2238d98fda4a9da92f770090b4cee5.shtml | F14: 从附件关系文件提取；链接有效性未重新核验
A15: 内嵌链接 | B15: 吴江 | C15: 苏州吴江区创新创业领军人才计划专题介绍_2026(2).docx | D15: 查看来源 6 | E15: https://www.wujiang.gov.cn/zgwj/rdwdjycy/202511/d992e24118854b429e6c7659609807c5.shtml | F15: 从附件关系文件提取；链接有效性未重新核验
A16: 内嵌链接 | B16: 吴江 | C16: 苏州吴江区创新创业领军人才计划专题介绍_2026(2).docx | D16: 查看来源 7 | E16: https://www.suzhou.gov.cn/szsrmzf/rdwd3/202601/85ecadc06f4646aebb6df03b6e5c3b2a.shtml | F16: 从附件关系文件提取；链接有效性未重新核验
... A174: 内嵌链接 | B174: 姑苏区（区级） | C174: 姑苏区领军人才政策(1).docx | D174: 苏州"1+8"人才政策发布（苏州日报） | E174: https://www.subaonet.com/2024/xwzt/xsdxzwxpz/xzw/0711/7roglPQr.html | F174: 从附件关系文件提取；链接有效性未重新核验
